<?xml version="1.0"?>
<robot name="simple_bot">

  <link name="base_footprint"/>

  <link name="base_link">
    <visual>
      <geometry><box size="0.4 0.3 0.15"/></geometry>
      <material name="blue"><color rgba="0.2 0.4 0.8 1"/></material>
    </visual>
    <collision><geometry><box size="0.4 0.3 0.15"/></geometry></collision>
    <inertial>
      <mass value="5.0"/>
      <inertia ixx="0.1" ixy="0" ixz="0" iyy="0.1" iyz="0" izz="0.1"/>
    </inertial>
  </link>

  <joint name="base_footprint_joint" type="fixed">
    <parent link="base_footprint"/>
    <child link="base_link"/>
    <origin xyz="0 0 0.1" rpy="0 0 0"/>
  </joint>

  <link name="left_wheel">
    <visual><geometry><cylinder radius="0.075" length="0.04"/></geometry></visual>
    <collision><geometry><cylinder radius="0.075" length="0.04"/></geometry></collision>
    <inertial>
      <mass value="0.5"/>
      <inertia ixx="0.001" ixy="0" ixz="0" iyy="0.001" iyz="0" izz="0.001"/>
    </inertial>
  </link>

  <joint name="left_wheel_joint" type="continuous">
    <parent link="base_link"/>
    <child link="left_wheel"/>
    <origin xyz="0 0.17 -0.025" rpy="-1.5708 0 0"/>
    <axis xyz="0 0 1"/>
  </joint>

  <link name="right_wheel">
    <visual><geometry><cylinder radius="0.075" length="0.04"/></geometry></visual>
    <collision><geometry><cylinder radius="0.075" length="0.04"/></geometry></collision>
    <inertial>
      <mass value="0.5"/>
      <inertia ixx="0.001" ixy="0" ixz="0" iyy="0.001" iyz="0" izz="0.001"/>
    </inertial>
  </link>

  <joint name="right_wheel_joint" type="continuous">
    <parent link="base_link"/>
    <child link="right_wheel"/>
    <origin xyz="0 -0.17 -0.025" rpy="-1.5708 0 0"/>
    <axis xyz="0 0 1"/>
  </joint>

  <link name="caster">
    <visual><geometry><sphere radius="0.03"/></geometry></visual>
    <collision><geometry><sphere radius="0.03"/></geometry></collision>
    <inertial>
      <mass value="0.1"/>
      <inertia ixx="0.0001" ixy="0" ixz="0" iyy="0.0001" iyz="0" izz="0.0001"/>
    </inertial>
  </link>

  <joint name="caster_joint" type="fixed">
    <parent link="base_link"/>
    <child link="caster"/>
    <origin xyz="0.15 0 -0.07" rpy="0 0 0"/>
  </joint>

  <!-- ttaches the Ignition diff-drive plugin. 
   subscribes to cmd_vel (in Gazebo) and publishes odom and tf (in Gazebo). 
   own bridge forwards those into ROS. -->
   <!-- by default stationary. -->
  <!-- /cmd_vel => [plugin] => /odom -->
   <gazebo>
    <plugin filename="ignition-gazebo-diff-drive-system"
            name="ignition::gazebo::systems::DiffDrive">
      <left_joint>left_wheel_joint</left_joint>
      <right_joint>right_wheel_joint</right_joint>
      <wheel_separation>0.34</wheel_separation>
      <wheel_radius>0.075</wheel_radius>
      <odom_publish_frequency>30</odom_publish_frequency>
      <topic>cmd_vel</topic>
      <odom_topic>odom</odom_topic>
      <tf_topic>tf</tf_topic>
      <frame_id>odom</frame_id>
      <child_frame_id>base_footprint</child_frame_id>
    </plugin>
  </gazebo>

</robot>
